Workbook

Sheet 需求主页
A1: 工作表保护密码：123456
B2: 文档日志
B4: 时间 | C4: 操作人 | D4: 操作 | E4: 操作内容
B5: 44827 | C5: orson | D5: 新建 | E5: 新建文档
B9: 设计内容
C10: 调整竞技场匹配规则
B12: 设计目的
C13: 1、降低高分段匹配机器人概率，尽可能避免断崖式分差情况
C14: 2、优化胜负得分计算
B16: 需求内容
B18: 调整1：匹配查找范围公式调整
C19: 原
D20: for，i=1，range=20*i*3，i<=2,i++
C21: 新
D22: for，i=1，range=c*i*(1+i*i*R*R/Rmax/Rmax)，i<=3,i++
C23: 验算工具（点击跳转）
B25: 调整2：胜负得分调整
C26: 原
D27: 胜利 | H27: 失败
C28: 进攻玩家 | D28: 玩家获得胜利积分*1.5 | H28: 降低排位分，原基础/8
C29: 防守玩家
C31: 新
D32: 胜利 | H32: 失败
C33: 进攻玩家 | D33: 玩家获得胜利积分*1.2 | H33: 降低排位分，原基础/4
C34: 防守玩家 | D34: 玩家获得胜利积分/2 | H34: 降低排位分，原基础/8
C36: 演算工具
C37: 黑色区域为输入项，输入分数查看结果 | H37: 结果内容下面两列
C38: 我方 - 进攻
C39: 进攻分 | D39: 防守分 | E39: 相对胜率 | F39: 得分 | G39: 扣分/2 | H39: 得分*1.2 | I39: 扣分/4
C40: 1000 | D40: 1000 | E40: =1/(1+POWER(10,(D40-C40)/400)) -> 0.5 | F40: =$K$43*(1-E40) -> 16 | G40: =$K$43*(0-E40)/2 -> -8 | H40: =F40*1.2 -> 19.2 | I40: =G40/2 -> -4
C41: 对方 - 防守
C42: 防守 | D42: 进攻 | E42: 相对胜率 | F42: 得分 | G42: 扣分/2 | H42: 得分/2 | I42: 扣分/8
C43: =D40 -> 1000 | D43: =C40 -> 1000 | E43: =1/(1+POWER(10,(D43-C43)/400)) -> 0.5 | F43: =$K$43*(1-E43) -> 16 | G43: =$K$43*(0-E43)/2 -> -8 | H43: =F43/2 -> 8 | I43: =G43/4 -> -2 | J43: K（常数） | K43: 32
B45: 调整3：胜利得分优化
C46: 最终计算结果，胜利得分不低于3分

Sheet 公式演算
A1: 工作表保护密码：123456 | B1: 32 | D1: 输入玩家分数查看结果
C2: 输入项 | D2: 玩家分数 | G2: 段位 | K2: 匹配结果 | N2: 段位 | Q2: 段位表
D3: 1000 | G3: =LOOKUP(D3,R:S,Q:Q) -> 1 | K3: 对手最小分数 | M3: =MIN(D16:F17) -> 1000 | N3: =LOOKUP(M3,R:S,Q:Q) -> 1 | Q3: 段位 | R3: Rmin | T3: Rmax | V3: 分数
D4: 排行榜最高分 | G4: 段位 | K4: 对手最大分数 | M4: =MAX(D16:F17) -> 1195 | N4: =LOOKUP(M4,R:S,Q:Q) -> 4 | Q4: 1 | R4: 1000 | T4: 1009 | V4: =T4-R4 -> 9
D5: 2000 | G5: =LOOKUP(D5,R:S,Q:Q) -> 6 | K5: 最小胜率 | M5: =1/(1+POWER(10,(M3-F6)/400)) -> 0.5 | Q5: 2 | R5: 1010 | T5: 1029 | V5: =T5-R5 -> 19
C6: R | D6: =D3 -> 1000 | E6: =D3 -> 1000 | F6: =D3 -> 1000 | K6: 最大胜率 | M6: =1/(1+POWER(10,(M4-F6)/400)) -> 0.24554596 | Q6: 3 | R6: 1030 | T6: 1099 | V6: =T6-R6 -> 69
C7: Rmin | D7: 1000 | E7: 1000 | F7: 1000 | K7: 最小得分 | M7: =B1*(1-M5) -> 16 | Q7: 4 | R7: 1100 | T7: 1299 | V7: =T7-R7 -> 199
C8: Rmax | D8: =D5 -> 2000 | E8: =D5 -> 2000 | F8: =D5 -> 2000 | K8: 最大得分 | M8: =B1*(1-M6) -> 24.142529 | Q8: 5 | R8: 1300 | T8: 1799 | V8: =T8-R8 -> 499
C9: C | D9: 20 | E9: 20 | F9: 20 | K9: 最小扣分 | M9: =B1*(0-M5)/4 -> -4 | Q9: 6 | R9: 1800 | T9: 2299 | V9: =T9-R9 -> 499
C10: i | D10: 1 | E10: 2 | F10: 3 | K10: 最大扣分 | M10: =B1*(0-M6)/4 -> -1.9643677 | Q10: 7 | R10: 2300 | T10: 2749 | V10: =T10-R10 -> 449
C11: R/Rmax | D11: =D6/D8 -> 0.5 | E11: =E6/E8 -> 0.5 | F11: =F6/F8 -> 0.5 | Q11: 8 | R11: 2750 | T11: 3399 | V11: =T11-R11 -> 649
B12: a | C12: C*i | D12: =D9*D10 -> 20 | E12: =E9*E10 -> 40 | F12: =F9*F10 -> 60 | Q12: 9 | R12: 3400 | T12: 4299 | V12: =T12-R12 -> 899
B13: b | C13: C*i*i*i*R/Rmax*R/Rmax | D13: =D9*D10*D10*D10*D11*D11 -> 5 | E13: =E9*E10*E10*E10*E11*E11 -> 40 | F13: =F9*F10*F10*F10*F11*F11 -> 135 | Q13: 10 | R13: 4300 | T13: -
B14: 范围±（结果） | C14: a+b | D14: =D12+D13 -> 25 | E14: =E12+E13 -> 80 | F14: =F12+F13 -> 195
D15: 对手范围1 | E15: 对手范围2 | F15: 对手范围3 | G15: 对手段位1 | H15: 对手段位2 | I15: 对手段位3
D16: =IF(D6-D14<D7,D7,D6-D14) -> 1000 | E16: =IF(E6-E14<E7,E7,E6-E14) -> 1000 | F16: =IF(F6-F14<F7,F7,F6-F14) -> 1000 | G16: =LOOKUP(D16,R:S,Q:Q) -> 1 | H16: =LOOKUP(E16,R:S,Q:Q) -> 1 | I16: =LOOKUP(F16,R:S,Q:Q) -> 1
D17: =IF(D6+D14>D8,D8,D6+D14) -> 1025 | E17: =IF(E6+E14>E8,E8,E6+E14) -> 1080 | F17: =IF(F6+F14>F8,F8,F6+F14) -> 1195 | G17: =LOOKUP(D17,R:S,Q:Q) -> 2 | H17: =LOOKUP(E17,R:S,Q:Q) -> 3 | I17: =LOOKUP(F17,R:S,Q:Q) -> 4
D18: 胜率范围1 | E18: 胜率范围2 | F18: 胜率范围2
D19: =1/(1+POWER(10,(D16-D6)/400)) -> 0.5 | E19: =1/(1+POWER(10,(E16-E6)/400)) -> 0.5 | F19: =1/(1+POWER(10,(F16-F6)/400)) -> 0.5
D20: =1/(1+POWER(10,(D6-D17)/400)) -> 0.53591593 | E20: =1/(1+POWER(10,(E6-E17)/400)) -> 0.61313682 | F20: =1/(1+POWER(10,(F6-F17)/400)) -> 0.75445404
D21: 胜利得分范围1 | E21: 胜利得分范围2 | F21: 胜利得分范围3
D22: =B1*(1-D19) -> 16 | E22: =B1*(1-E19) -> 16 | F22: =B1*(1-F19) -> 16
D23: =B1*(1-D20) -> 14.85069 | E23: =B1*(1-E20) -> 12.379622 | F23: =B1*(1-F20) -> 7.8574707
D24: 失败扣分范围1 | E24: 失败扣分范围2 | F24: 失败扣分范围3
D25: =B1*(0-D19)/4 -> -4 | E25: =B1*(0-E19)/4 -> -4 | F25: =B1*(0-F19)/4 -> -4
D26: =B1*(0-D20)/4 -> -4.2873274 | E26: =B1*(0-E20)/4 -> -4.9050946 | F26: =B1*(0-F20)/4 -> -6.0356323
D30: =D12*(1+D10*D10*D11*D11) -> 25 | E30: =E12*(1+E10*E10*E11*E11) -> 80 | F30: =F12*(1+F10*F10*F11*F11) -> 195
C31: 完全公式计算范围 | D31: =D12*(1+D10*D10*D6*D6/D8/D8) -> 25 | E31: =E12*(1+E10*E10*E6*E6/E8/E8) -> 80 | F31: =F12*(1+F10*F10*F6*F6/F8/F8) -> 195

Sheet 草稿
A1: 工作表保护密码：123456
D2: K | E2: 32
D3: K | E3: =E2 -> 32 | N3: 进攻 | O3: /4 | P3: /2 | Q3: 防守 | R3: /8 | S3: /4
B4: 工具1：根据竞技场情况，计算匹配结果 | N4: =K10*1.5 -> 15.216673 | O4: =L10/2 -> -5.4638879 | P4: =L10/1.5 -> -7.2851839 | Q4: =K10/2 -> 5.0722242 | R4: =L10/4 -> -2.7319439 | S4: =L10/2 -> -5.4638879
B5: 输入内容 | N5: =K11*1.5 -> 23.49811 | O5: =L11/2 -> -4.0836484 | P5: =L11/1.5 -> -5.4448645 | Q5: =K11/2 -> 7.8327032 | R5: =L11/4 -> -2.0418242
B6: 玩家分数 | E6: 最高分数 | F6: 连胜 | I6: 玩家段位 | N6: =K12*1.5 -> 31.900867 | O6: =L12/2 -> -2.6831888 | P6: =L12/1.5 -> -3.5775851 | Q6: =K12/2 -> 10.633622 | R6: =L12/4 -> -1.3415944
B7: 3400 | E7: 10000 | F7: 0 | I7: =LOOKUP(B7,[1]段位表!C3:D12,[1]段位表!J3:J12) -> 9
B8: 演算结果 | R8: 公式拆分 | W8: 相乘
C9: R | D9: Rmin | E9: Rmax | F9: a | G9: C | H9: 对手分 | I9: 对手段位 | J9: 相对胜率 | K9: 得分 | L9: 扣分 | M9: 胜利得分 | N9: 失败扣分 | O9: 公式计算 | P9: 拆分合并 | R9: R | T9: R-Rmin | U9: Rmin/R*0.1 | W9: (R-Rmin)*Rmin/R*0.1
B10: 1 | C10: =B7 -> 3400 | D10: 1000 | E10: =E7 -> 10000 | F10: =F7 -> 0 | G10: 20 | H10: =IF(P10<1000,1000,P10) -> 3266.6667 | I10: =LOOKUP(H10,[1]段位表!$C$3:$D$12,[1]段位表!$J$3:$J$12) -> 8 | J10: =1/(1+POWER(10,(H10-C10)/400)) -> 0.68298599 | K10: =$E$3*(1-J10) -> 10.144448 | L10: =$E$3*(0-J10)/2 -> -10.927776 | M10: =K10*1.5 -> 15.216673 | N10: =L10/4 -> -2.7319439 | O10: =C10-(1.7*D10*(C10-D10))/(C10*(F10+9)) -> 3266.6667 | P10: =R10-T10*U10*17/(F10+9) -> 3266.6667 | R10: =C10 -> 3400 | T10: =C10-D10 -> 2400 | U10: =D10/C10*0.1 -> 0.029411765 | W10: =T10*U10 -> 70.588235 | Y10: =17/(F10+9) -> 1.8888889 | Z10: =W10*Y10 -> 133.33333
B11: 2 | C11: =B7 -> 3400 | D11: 1000 | E11: =E7 -> 10000 | F11: =F7 -> 0 | G11: 20 | H11: =(H10+H12)/2 -> 3392.7333 | I11: =LOOKUP(H11,[1]段位表!$C$3:$D$12,[1]段位表!$J$3:$J$12) -> 8 | J11: =1/(1+POWER(10,(H11-C11)/400)) -> 0.51045605 | K11: =$E$3*(1-J11) -> 15.665406 | L11: =$E$3*(0-J11)/2 -> -8.1672968 | M11: =K11*1.5 -> 23.49811 | N11: =L11/4 -> -2.0418242 | O11: =C11+((0.1*C11*(E11-C11)*(F11+9))/(34*E11))-((1.7*D11*(C11-D11))/(2*C11*(F11+9))) -> 3392.7333 | R11: R | T11: Rmax-R | U11: R/Rmax*0.1 | W11: (Rmax-R)*(R/Rmax*0.1)
B12: 3 | C12: =B7 -> 3400 | D12: 1000 | E12: =E7 -> 10000 | F12: =F7 -> 0 | G12: 20 | H12: =IF(P12<1000,1000,P12) -> 3518.8 | I12: =LOOKUP(H12,[1]段位表!$C$3:$D$12,[1]段位表!$J$3:$J$12) -> 9 | J12: =1/(1+POWER(10,(H12-C12)/400)) -> 0.3353986 | K12: =$E$3*(1-J12) -> 21.267245 | L12: =$E$3*(0-J12)/2 -> -5.3663777 | M12: =K12*1.5 -> 31.900867 | N12: =L12/4 -> -1.3415944 | O12: =C12+(0.1*C12*(E12-C12)*(F12+9))/(17*E12) -> 3518.8 | P12: =R12+T12*U12*(F12+9)/17 -> 3518.8 | R12: =C12 -> 3400 | T12: =E12-C12 -> 6600 | U12: =C12/E12*0.1 -> 0.034 | W12: =T12*U12 -> 224.4 | Y12: =(F12+9)/17 -> 0.52941176 | Z12: =W12*Y12 -> 118.8 | AA12: =+++++++++++++++++++++++++++++++++++++++++++++++++++++++++++++++++++++++++++++++++++++++++7 -> 7
B13: 工具2：直接输入双方分数，获得得分情况
B14: 输入内容（手动输入“我方”、“对手分”） | N14: =M10/2 -> 7.6083363
B15: R | F15: 玩家段位 | H15: 对手分 | I15: 对手段位 | J15: 相对胜率 | K15: 得分 | L15: 扣分 | N15: =M11/2 -> 11.749055 | O15: =O10-60 -> 3206.6667 | P15: =O10+60 -> 3326.6667 | R15: =O10-120 -> 3146.6667 | S15: =O10+120 -> 3386.6667 | U15: =O10-180 -> 3086.6667 | V15: =O10+180 -> 3446.6667
B16: 5000 | F16: =LOOKUP(B16,[1]段位表!$C$3:$D$12,[1]段位表!$J$3:$J$12) -> 10 | H16: 5000 | I16: =LOOKUP(H16,[1]段位表!$C$3:$D$12,[1]段位表!$J$3:$J$12) -> 10 | J16: =1/(1+POWER(10,(H16-B16)/400)) -> 0.5 | K16: =$E$3*(1-J16) -> 16 | L16: =$E$3*(0-J16)/2 -> -8 | N16: =M12/2 -> 15.950434 | O16: =O11-60 -> 3332.7333 | P16: =O11+60 -> 3452.7333 | R16: =O11-120 -> 3272.7333 | S16: =O11+120 -> 3512.7333 | U16: =O11-180 -> 3212.7333 | V16: =O11+180 -> 3572.7333
O17: =O12-60 -> 3458.8 | P17: =O12+60 -> 3578.8 | R17: =O12-120 -> 3398.8 | S17: =O12+120 -> 3638.8 | U17: =O12-180 -> 3338.8 | V17: =O12+180 -> 3698.8
A19: 草稿区域
B21: 段位 | C21: Rmin | E21: Rmax | G21: 升段 | I21: 场次 | J21: 段位 | L21: 胜利得分 | M21: 失败扣分 | N21: 期望胜率 | P21: 升段分差 | R21: 期望每场得分 | S21: 需要场数 | U21: 大R
B22: 1 | C22: 1000 | E22: 1009 | G22: 10 | I22: 0.625 | J22: 1 | L22: 24 | M22: 6 | N22: 1 | P22: =E22-C22 -> 9 | R22: =L22*N22-M22*(1-N22) -> 24 | S22: =P22/R22 -> 0.375 | U22: 1 | W22: 38 | X22: =P22/W22 -> 0.23684211
B23: 2 | C23: 1010 | E23: 1029 | G23: 20 | I23: 1.25 | J23: 2 | L23: 24 | M23: 6 | N23: 0.9 | P23: =E23-C23 -> 19 | R23: =L23*N23-M23*(1-N23) -> 21 | S23: =P23/R23 -> 0.9047619 | U23: 1 | W23: 38 | X23: =P23/W23 -> 0.5
B24: 3 | C24: 1030 | E24: 1099 | G24: 70 | I24: 4.375 | J24: 3 | L24: 24 | M24: 6 | N24: 0.9 | P24: =E24-C24 -> 69 | R24: =L24*N24-M24*(1-N24) -> 21 | S24: =P24/R24 -> 3.2857143 | U24: 1 | W24: 38 | X24: =P24/W24 -> 1.8157895
B25: 4 | C25: 1100 | E25: 1299 | G25: 200 | I25: 12.5 | J25: 4 | L25: 24 | M25: 6 | N25: 0.8 | P25: =E25-C25 -> 199 | R25: =L25*N25-M25*(1-N25) -> 18 | S25: =P25/R25 -> 11.055556 | U25: 1 | W25: 38 | X25: =P25/W25 -> 5.2368421
B26: 5 | C26: 1300 | E26: 1799 | G26: 500 | I26: 31.25 | J26: 5 | L26: 24 | M26: 6 | N26: 0.8 | P26: =E26-C26 -> 499 | R26: =L26*N26-M26*(1-N26) -> 18 | S26: =P26/R26 -> 27.722222 | U26: 1 | W26: 38 | X26: =P26/W26 -> 13.131579
B27: 6 | C27: 1800 | E27: 2299 | G27: 500 | I27: 31.25 | J27: 6 | L27: 24 | M27: 6 | N27: 0.8 | P27: =E27-C27 -> 499 | R27: =L27*N27-M27*(1-N27) -> 18 | S27: =P27/R27 -> 27.722222 | U27: 1 | W27: 38 | X27: =P27/W27 -> 13.131579
B28: 7 | C28: 2300 | E28: 2749 | G28: 450 | I28: 28.125 | J28: 7 | L28: 24 | M28: 6 | N28: 0.7 | P28: =E28-C28 -> 449 | R28: =L28*N28-M28*(1-N28) -> 15 | S28: =P28/R28 -> 29.933333 | U28: 1 | W28: 38 | X28: =P28/W28 -> 11.815789
B29: 8 | C29: 2750 | E29: 3399 | G29: 650 | I29: 40.625 | J29: 8 | L29: 24 | M29: 6 | N29: 0.5 | P29: =E29-C29 -> 649 | R29: =L29*N29-M29*(1-N29) -> 9 | S29: =P29/R29 -> 72.111111 | U29: 1 | W29: 38 | X29: =P29/W29 -> 17.078947
B30: 9 | C30: 3400 | D30: - | E30: 4299 | G30: 900 | I30: 56.25 | J30: 9 | L30: 24 | M30: 6 | N30: 0.5 | P30: =E30-C30 -> 899 | R30: =L30*N30-M30*(1-N30) -> 9 | S30: =P30/R30 -> 99.888889 | U30: 1 | W30: 38 | X30: =P30/W30 -> 23.657895
B31: 10 | C31: 4300 | E31: - | J31: 10
L32: 2100 | M32: 2000 | S32: 1-9段所需场数
B33: 1、失败扣分的算法 | N33: =C30-C22 -> 2400 | O33: 300 | P33: 330 | S33: =SUM(S22:S30) -> 272.99881 | X33: =SUM(X22:X30) -> 86.605263
C34: 现在是/8，要改成/4 | O34: =N33/O33 -> 8
N35: =C31-C30 -> 900 | O35: =N35/O33 -> 3
B36: 2、循环查询规则，放大区间 | G36: C | H36: 1 | I36: 2 | J36: 3 | K36: 4 | L36: 5
C37: for，i=1，range=20*i*3，i<=2,i++ | G37: 20 | H37: =$G$37*H36*3 -> 60 | I37: =$G$37*I36*3 -> 120 | J37: =$G$37*J36*3 -> 180
G39: C | H39: 20 | I39: 20 | J39: 20
G40: i*i | H40: =H36*H36 -> 1 | I40: =I36*I36 -> 4 | J40: =J36*J36 -> 9
A41: e | H41: =H39*H40 -> 20 | I41: =I39*I40 -> 80 | J41: =J39*J40 -> 180
G42: i*(i+1) | H42: =H$36*(H$36+1) -> 2 | I42: =I$36*(I$36+1) -> 6 | J42: =J$36*(J$36+1) -> 12 | P42: i=1 | Q42: i=2 | R42: i=3
H43: =H$39*H42 -> 40 | I43: =I$39*I42 -> 120 | J43: =J$39*J42 -> 240 | Q43: 60 | R43: 155
...
